Traceback (most recent call last):
  File "/home/vikrambhatt/anaconda3/lib/python3.8/site-packages/jupyter_cache/executors/utils.py", line 51, in single_nb_execution
    executenb(
  File "/home/vikrambhatt/anaconda3/lib/python3.8/site-packages/nbclient/client.py", line 1087, in execute
    return NotebookClient(nb=nb, resources=resources, km=km, **kwargs).execute()
  File "/home/vikrambhatt/anaconda3/lib/python3.8/site-packages/nbclient/util.py", line 74, in wrapped
    return just_run(coro(*args, **kwargs))
  File "/home/vikrambhatt/anaconda3/lib/python3.8/site-packages/nbclient/util.py", line 53, in just_run
    return loop.run_until_complete(coro)
  File "/home/vikrambhatt/anaconda3/lib/python3.8/asyncio/base_events.py", line 616, in run_until_complete
    return future.result()
  File "/home/vikrambhatt/anaconda3/lib/python3.8/site-packages/nbclient/client.py", line 540, in async_execute
    await self.async_execute_cell(
  File "/home/vikrambhatt/anaconda3/lib/python3.8/site-packages/nbclient/client.py", line 832, in async_execute_cell
    self._check_raise_for_error(cell, exec_reply)
  File "/home/vikrambhatt/anaconda3/lib/python3.8/site-packages/nbclient/client.py", line 740, in _check_raise_for_error
    raise CellExecutionError.from_cell_and_msg(cell, exec_reply['content'])
nbclient.exceptions.CellExecutionError: An error occurred while executing the following cell:
------------------
acct withdraw 40
------------------

[31mjava.lang.Error: insufficient funds[39m
  ammonite.$sess.cmd0$Helper$BankAccount.withdraw([32mcmd0.sc[39m:[32m10[39m)
  ammonite.$sess.cmd3$Helper.<init>([32mcmd3.sc[39m:[32m1[39m)
  ammonite.$sess.cmd3$.<clinit>([32mcmd3.sc[39m:[32m7[39m)
: [31mjava.lang.Error: insufficient funds[39m
  ammonite.$sess.cmd0$Helper$BankAccount.withdraw([32mcmd0.sc[39m:[32m10[39m)
  ammonite.$sess.cmd3$Helper.<init>([32mcmd3.sc[39m:[32m1[39m)
  ammonite.$sess.cmd3$.<clinit>([32mcmd3.sc[39m:[32m7[39m)

